Traceback (most recent call last):
  File "/home/mz071159/miniconda3/lib/python3.9/site-packages/pandas/core/indexes/base.py", line 3652, in get_loc
    return self._engine.get_loc(casted_key)
  File "pandas/_libs/index.pyx", line 147, in pandas._libs.index.IndexEngine.get_loc
  File "pandas/_libs/index.pyx", line 176, in pandas._libs.index.IndexEngine.get_loc
  File "pandas/_libs/hashtable_class_helper.pxi", line 7080, in pandas._libs.hashtable.PyObjectHashTable.get_item
  File "pandas/_libs/hashtable_class_helper.pxi", line 7088, in pandas._libs.hashtable.PyObjectHashTable.get_item
KeyError: 'area_convex'

The above exception was the direct cause of the following exception:

Traceback (most recent call last):
  File "/rwthfs/rz/cluster/home/mz071159/random_projects_lukas/find_eut_isles_skript.py", line 33, in <module>
    mean_width=df.loc[(df['area_convex']>5),'axis_minor_length'].mean()
  File "/home/mz071159/miniconda3/lib/python3.9/site-packages/pandas/core/frame.py", line 3761, in __getitem__
    indexer = self.columns.get_loc(key)
  File "/home/mz071159/miniconda3/lib/python3.9/site-packages/pandas/core/indexes/base.py", line 3654, in get_loc
    raise KeyError(key) from err
KeyError: 'area_convex'
srun: error: ncm0053: task 0: Exited with exit code 1
